Traceback (most recent call last):
  File "/home/runner/.cache/pypoetry/virtualenvs/ccs-oj5MS1KF-py3.9/lib/python3.9/site-packages/jupyter_cache/executors/utils.py", line 58, in single_nb_execution
    executenb(
  File "/home/runner/.cache/pypoetry/virtualenvs/ccs-oj5MS1KF-py3.9/lib/python3.9/site-packages/nbclient/client.py", line 1204, in execute
    return NotebookClient(nb=nb, resources=resources, km=km, **kwargs).execute()
  File "/home/runner/.cache/pypoetry/virtualenvs/ccs-oj5MS1KF-py3.9/lib/python3.9/site-packages/nbclient/util.py", line 84, in wrapped
    return just_run(coro(*args, **kwargs))
  File "/home/runner/.cache/pypoetry/virtualenvs/ccs-oj5MS1KF-py3.9/lib/python3.9/site-packages/nbclient/util.py", line 62, in just_run
    return loop.run_until_complete(coro)
  File "/opt/hostedtoolcache/Python/3.9.15/x64/lib/python3.9/asyncio/base_events.py", line 647, in run_until_complete
    return future.result()
  File "/home/runner/.cache/pypoetry/virtualenvs/ccs-oj5MS1KF-py3.9/lib/python3.9/site-packages/nbclient/client.py", line 663, in async_execute
    await self.async_execute_cell(
  File "/home/runner/.cache/pypoetry/virtualenvs/ccs-oj5MS1KF-py3.9/lib/python3.9/site-packages/nbclient/client.py", line 965, in async_execute_cell
    await self._check_raise_for_error(cell, cell_index, exec_reply)
  File "/home/runner/.cache/pypoetry/virtualenvs/ccs-oj5MS1KF-py3.9/lib/python3.9/site-packages/nbclient/client.py", line 862, in _check_raise_for_error
    raise CellExecutionError.from_cell_and_msg(cell, exec_reply_content)
nbclient.exceptions.CellExecutionError: An error occurred while executing the following cell:
------------------
import os, sys, warnings
import json
import itertools as it
from collections import OrderedDict, defaultdict
import numpy as np
from ase import Atoms
from ase import io
from ase.calculators.neighborlist import NeighborList
import ase.db as db
from tqdm import tqdm 
from ccs.scripts.ccs_fetch import ccs_fetch as ccs_fetch
from ccs.fitting.main import twp_fit as ccs_fit

from ccs.common.exceptions import ScriptError 
from ccs.ase_calculator.ccs_ase_calculator import CCS

base_dir=os.getcwd()
os.chdir(base_dir)
print('Base dir is:', base_dir)
warnings.filterwarnings('ignore')

------------------

[0;31m---------------------------------------------------------------------------[0m
[0;31mModuleNotFoundError[0m                       Traceback (most recent call last)
Cell [0;32mIn [1], line 11[0m
[1;32m      9[0m [38;5;28;01mimport[39;00m [38;5;21;01mase[39;00m[38;5;21;01m.[39;00m[38;5;21;01mdb[39;00m [38;5;28;01mas[39;00m [38;5;21;01mdb[39;00m
[1;32m     10[0m [38;5;28;01mfrom[39;00m [38;5;21;01mtqdm[39;00m [38;5;28;01mimport[39;00m tqdm 
[0;32m---> 11[0m [38;5;28;01mfrom[39;00m [38;5;21;01mccs[39;00m[38;5;21;01m.[39;00m[38;5;21;01mscripts[39;00m[38;5;21;01m.[39;00m[38;5;21;01mccs_fetch[39;00m [38;5;28;01mimport[39;00m ccs_fetch [38;5;28;01mas[39;00m ccs_fetch
[1;32m     12[0m [38;5;28;01mfrom[39;00m [38;5;21;01mccs[39;00m[38;5;21;01m.[39;00m[38;5;21;01mfitting[39;00m[38;5;21;01m.[39;00m[38;5;21;01mmain[39;00m [38;5;28;01mimport[39;00m twp_fit [38;5;28;01mas[39;00m ccs_fit
[1;32m     14[0m [38;5;28;01mfrom[39;00m [38;5;21;01mccs[39;00m[38;5;21;01m.[39;00m[38;5;21;01mcommon[39;00m[38;5;21;01m.[39;00m[38;5;21;01mexceptions[39;00m [38;5;28;01mimport[39;00m ScriptError 

[0;31mModuleNotFoundError[0m: No module named 'ccs.scripts.ccs_fetch'
ModuleNotFoundError: No module named 'ccs.scripts.ccs_fetch'

